import pytest
import asyncio
import aiohttp
import random
from typing import Dict, Any, List, Optional
from unittest.mock import patch, AsyncMock
from src.core.error_recovery import error_recovery
from src.core.circuit_breaker import circuit_breaker_registry
from src.core.lock_manager import distributed_lock_manager
from src.core.config_manager import config_manager

class ChaosTest:
    """Base class for chaos testing scenarios"""
    async def setup(self) -> None:
        """Setup test environment"""
        pass

    async def teardown(self) -> None:
        """Cleanup after test"""
        pass

    async def inject_failure(self) -> None:
        """Inject failure into the system"""
        pass

    async def verify_recovery(self) -> bool:
        """Verify system recovered correctly"""
        return True

class NetworkFailureTest(ChaosTest):
    """Test system resilience to network failures"""
    
    async def inject_failure(self) -> None:
        """Simulate network partition"""
        with patch('aiohttp.ClientSession.get', side_effect=aiohttp.ClientError):
            # Trigger multiple operations during network failure
            await asyncio.gather(
                self._test_api_resilience(),
                self._test_cache_resilience(),
                self._test_db_resilience()
            )

    async def _test_api_resilience(self) -> None:
        """Test API endpoint resilience"""
        try:
            async with aiohttp.ClientSession() as session:
                await session.get('http://localhost:8000/api/v1/status')
        except aiohttp.ClientError:
            # Verify error recovery kicked in
            assert error_recovery.last_error is not None
            assert error_recovery.recovery_attempts > 0

    async def _test_cache_resilience(self) -> None:
        """Test cache resilience"""
        # Verify cache fallback mechanisms
        pass

    async def _test_db_resilience(self) -> None:
        """Test database resilience"""
        # Verify database retry mechanisms
        pass

class ServiceDisruptionTest(ChaosTest):
    """Test system resilience to service disruptions"""
    
    async def inject_failure(self) -> None:
        """Simulate service disruptions"""
        # Simulate Redis failure
        with patch('aioredis.Redis.get', side_effect=ConnectionError):
            await self._test_redis_resilience()

        # Simulate database failure
        with patch('asyncpg.Connection.fetch', side_effect=ConnectionError):
            await self._test_db_resilience()

    async def _test_redis_resilience(self) -> None:
        """Test Redis failure handling"""
        # Verify circuit breaker activation
        assert await circuit_breaker_registry.get_breaker('redis').is_open()

    async def _test_db_resilience(self) -> None:
        """Test database failure handling"""
        # Verify circuit breaker activation
        assert await circuit_breaker_registry.get_breaker('database').is_open()

class ResourceExhaustionTest(ChaosTest):
    """Test system resilience to resource exhaustion"""
    
    async def inject_failure(self) -> None:
        """Simulate resource exhaustion"""
        # Simulate memory pressure
        await self._test_memory_pressure()
        
        # Simulate CPU pressure
        await self._test_cpu_pressure()
        
        # Simulate disk pressure
        await self._test_disk_pressure()

    async def _test_memory_pressure(self) -> None:
        """Test memory pressure handling"""
        large_data = [f"data_{i}" * 1000000 for i in range(1000)]
        # Verify memory management kicks in
        assert error_recovery.is_resource_pressure_detected()

    async def _test_cpu_pressure(self) -> None:
        """Test CPU pressure handling"""
        # Simulate CPU-intensive tasks
        pass

    async def _test_disk_pressure(self) -> None:
        """Test disk pressure handling"""
        # Simulate disk space issues
        pass

@pytest.mark.chaos
class TestChaosResilience:
    """Main chaos testing suite"""
    
    @pytest.fixture
    async def setup_chaos_tests(self):
        """Setup chaos testing environment"""
        # Initialize test components
        await error_recovery.initialize()
        await circuit_breaker_registry.initialize()
        await distributed_lock_manager.initialize()
        await config_manager.initialize()
        
        yield
        
        # Cleanup
        await error_recovery.shutdown()
        await circuit_breaker_registry.shutdown()
        await distributed_lock_manager.shutdown()
        await config_manager.shutdown()

    @pytest.mark.asyncio
    async def test_network_failure(self, setup_chaos_tests):
        """Test system resilience to network failures"""
        test = NetworkFailureTest()
        await test.setup()
        await test.inject_failure()
        assert await test.verify_recovery()
        await test.teardown()

    @pytest.mark.asyncio
    async def test_service_disruption(self, setup_chaos_tests):
        """Test system resilience to service disruptions"""
        test = ServiceDisruptionTest()
        await test.setup()
        await test.inject_failure()
        assert await test.verify_recovery()
        await test.teardown()

    @pytest.mark.asyncio
    async def test_resource_exhaustion(self, setup_chaos_tests):
        """Test system resilience to resource exhaustion"""
        test = ResourceExhaustionTest()
        await test.setup()
        await test.inject_failure()
        assert await test.verify_recovery()
        await test.teardown()

    @pytest.mark.asyncio
    async def test_concurrent_failures(self, setup_chaos_tests):
        """Test system resilience to multiple concurrent failures"""
        tests = [
            NetworkFailureTest(),
            ServiceDisruptionTest(),
            ResourceExhaustionTest()
        ]
        
        # Setup all tests
        await asyncio.gather(*[test.setup() for test in tests])
        
        # Inject failures concurrently
        await asyncio.gather(*[test.inject_failure() for test in tests])
        
        # Verify recovery
        results = await asyncio.gather(*[test.verify_recovery() for test in tests])
        assert all(results)
        
        # Cleanup
        await asyncio.gather(*[test.teardown() for test in tests]) 